Workbook
Name Bezetting: 'Basis waarden en tabellen'!$D$17:$Z$24
Name BezonningGevelEzonWinter_description: Invoer!$E$47
Name BezonningGevelEzonWinter_unit: Invoer!$J$47
Name BezonningGevelEzonWinter_value: Invoer!$I$47
Name BezonningGevelEzonZomer_description: Invoer!$E$46
Name BezonningGevelEzonZomer_unit: Invoer!$J$46
Name BezonningGevelEzonZomer_value: Invoer!$I$46
Name C_massa: Coeefficienten!$D$112:$H$117
Name ClimateChangeEffectEzonWinter_description: Invoer!$E$40
Name ClimateChangeEffectEzonWinter_unit: Invoer!$J$40
Name ClimateChangeEffectEzonWinter_value: Invoer!$M$40
Name ClimateChangeEffectEzonZomer_description: Invoer!$E$39
Name ClimateChangeEffectEzonZomer_unit: Invoer!$J$39
Name ClimateChangeEffectEzonZomer_value: Invoer!$M$39
Name ClimateChangeEffectTgem_description: Invoer!$E$36
Name ClimateChangeEffectTgem_unit: Invoer!$J$36
Name ClimateChangeEffectTgem_value: Invoer!$M$36
Name ClimateChangeEffectTgemWinter_description: Invoer!$E$38
Name ClimateChangeEffectTgemWinter_unit: Invoer!$J$38
Name ClimateChangeEffectTgemWinter_value: Invoer!$M$38
Name ClimateChangeEffectTgemZomer_description: Invoer!$E$37
Name ClimateChangeEffectTgemZomer_unit: Invoer!$J$37
Name ClimateChangeEffectTgemZomer_value: Invoer!$M$37
Name CO2RegelingVentilatie_description: Invoer!$E$25
Name CO2RegelingVentilatie_value: Invoer!$F$25
Name Collectief: Coeefficienten!$D$19:$H$23
Name Collector: Tabellen!$B$64:$C$67
Name Constructie: Tabellen!$B$49:$C$53
Name ConstructieWijze_description: Invoer!$E$16
Name ConstructieWijze_value: Invoer!$F$16
Name COP: Coeefficienten!$E$19:$H$23
Name COP_: Coeefficienten!$D$19:$H$23
Name corner_correctie: Tabellen!$Q$28
Name corner_correction: Tabellen!$O$20:$R$24
Name Dak: Tabellen!$B$36:$C$38
Name Dak_description: Invoer!$E$14
Name Dak_U: Tabellen!$B$36:$D$38
Name Dak_Uw: Coeefficienten!$D$121:$G$123
Name Dak_value: Invoer!$F$14
Name DF_ratio: Coeefficienten!$F$69:$S$70
Name Douche: Tabellen!$B$70:$C$72
Name douche_red: Coeefficienten!$E$32:$F$34
Name douche_reductie: Coeefficienten!$D$32:$F$34
Name Douchewtw_description: Invoer!$E$24
Name Douchewtw_value: Invoer!$F$24
Name dT_h: Coeefficienten!$M$138:$W$139
Name Gebouwconcept: Tabellen!$E$41:$K$45
Name Gegevens: Tabellen!$B$76:$C$77
Name inkoop_tabel: Coeefficienten!$N$18:$R$23
Name input_BerekendDaglichtFactor_description: Invoer!$E$48
Name input_BerekendDaglichtFactor_value: Invoer!$I$49
Name input_DakaAnwezigheid_value: Invoer!$F$13
Name input_DakAnwezigheid_description: Invoer!$E$13
Name input_GrootteApartement_description: Invoer!$E$5
Name input_GrootteApartement_unit: Invoer!$J$5
Name input_GrootteApartement_value: Invoer!$I$5
Name input_OppervlakBuitenGevel_description: Invoer!$E$7
Name input_OppervlakBuitenGevel_unit: Invoer!$J$7
Name input_OppervlakBuitenGevel_value: Invoer!$I$7
Name input_Orientatie_description: Invoer!$E$6

Sheet Scenarios
D2: Scenario Selection | E2: SC4
D5: Ruimtelijke modellen
I6: Traditionele ' glas' en techniek architectuur met beton | J6: Natuurlijk + warmtepompen | K6: Natuurlijk innovatief; indirecte wtw & slimme SV | L6: Passive House + SV voor tapwater
D7: Plan brugers 1
D8: Plan Burgers 2
D9: Masterplan
D10: Torens
D11: Gallerijen
C14: 1 | D14: Handmatig in te voeren parameters: | I14: SC1 | J14: SC2 | K14: SC3 | L14: SC4
C15: 2 | D15: Dak (indien appartement dak heeft) | E15: eventueel | F15: 1 | I15: 2 | J15: 2 | K15: 3 | L15: 3
C16: 3 | D16: Constructie wijze | I16: 5 | J16: 1 | K16: 1 | L16: 3
C17: 4 | D17: Ventilatiesysteem | I17: 4 | J17: 1 | K17: 2 | L17: 3
C18: 5 | D18: Koude/warmte | I18: 2 | J18: 1 | K18: 4 | L18: 3
C19: 6 | D19: Zonnecollector | I19: 1 | J19: 3 | K19: 1 | L19: 3
C20: 7 | D20: Douche wtw | I20: 1 | J20: 2 | K20: 3 | L20: 2
C21: 8 | D21: CO2 regeling ventilatie | I21: 2 | J21: 2 | K21: 2 | L21: 2
D23: Parameters:
D24: Constructie wijze
D25: % Glas | I25: 0.4 | J25: =VLOOKUP(Scenarios!J17,Tabellen!$E$42:$K$45,7) -> 0.4 | K25: =VLOOKUP(Scenarios!K17,Tabellen!$E$42:$K$45,7) -> 0.4 | L25: =VLOOKUP(Scenarios!L17,Tabellen!$E$42:$K$45,7) -> 0.3
D26: U dichte gevel | I26: =VLOOKUP(Scenarios!I19,Tabellen!$E$42:$K$45,2) -> 0.3 | J26: =VLOOKUP(Scenarios!J19,Tabellen!$E$42:$K$45,2) -> 0.2 | K26: =VLOOKUP(Scenarios!K19,Tabellen!$E$42:$K$45,2) -> 0.3 | L26: =VLOOKUP(Scenarios!L19,Tabellen!$E$42:$K$45,2) -> 0.2
D27: Uglas | I27: =VLOOKUP(Scenarios!I20,Tabellen!$E$42:$K$45,3) -> 1.2 | J27: =VLOOKUP(Scenarios!J20,Tabellen!$E$42:$K$45,3) -> 1.2 | K27: =VLOOKUP(Scenarios!K20,Tabellen!$E$42:$K$45,3) -> 0.8 | L27: =VLOOKUP(Scenarios!L20,Tabellen!$E$42:$K$45,3) -> 1.2
D28: Dak | I28: =IF(I15=2,"zwart","groen") -> zwart | J28: =IF(J15=2,"zwart","groen") -> zwart | K28: =IF(K15=2,"zwart","groen") -> groen | L28: =IF(L15=2,"zwart","groen") -> groen
D29: Constructie | I29: hout | J29: hout | K29: hybride | L29: beton
D30: Ventilatiesysteem | I30: =VLOOKUP(I$17,Ventilatie,2) -> Balans met WTW | J30: =VLOOKUP(J$17,Ventilatie,2) -> Nat. toevoer + mech. Afzuiging | K30: =VLOOKUP(K$17,Ventilatie,2) -> Nat toevoer met indirecte ww | L30: =VLOOKUP(L$17,Ventilatie,2) -> Passive House
D31: Koude/warmte | I31: =VLOOKUP(I18,Warmte,2) -> Warmtepomp WKO | J31: =VLOOKUP(J18,Warmte,2) -> Warmtepomp lucht | K31: =VLOOKUP(K18,Warmte,2) -> Stadsverwarming Tapwater + warmtepomp | L31: =VLOOKUP(L18,Warmte,2) -> Stadsverwarming + Koelmachine
D32: Zonnecollector | I32: =VLOOKUP(I19,Collector,2) -> Geen | J32: =VLOOKUP(J19,Collector,2) -> Standaard | K32: =VLOOKUP(K19,Collector,2) -> Geen | L32: =VLOOKUP(L19,Collector,2) -> Standaard
D33: Douche wtw | I33: collectief | J33: collectief | K33: individueel | L33: nee
D34: CO2 regeling ventilatie | I34: =VLOOKUP(Scenarios!I20,Douche,2) -> geen | J34: =VLOOKUP(Scenarios!J20,Douche,2) -> individueel | K34: =VLOOKUP(Scenarios!K20,Douche,2) -> collectief | L34: =VLOOKUP(Scenarios!L20,Douche,2) -> individueel
E36: ja | F36: nee | I36: ja | J36: ja | K36: ja | L36: ja
D37: Locatie gegevens Tgem | E37: =(E38+E39)/2 -> -0.05 | F37: 0 | G37: ΔT
D38: Locatie gegevens Tgem.zomer | E38: -0.3 | F38: 0 | G38: ΔT
D39: Locatie gegevens Tgem.winter | E39: 0.2 | F39: 0 | G39: ΔT
D40: Locatie gegevens Ezon.zomer | E40: 75 | F40: 0 | G40: ΔP
D41: Locatie gegevensEzon.winter | E41: 30 | F41: 0 | G41: ΔP
E43: ja | F43: nee | I43: nee | J43: nee | K43: nee | L43: nee
D44: Climate Change effect Tgem | E44: =(E45+E46)/2 -> 1.55 | F44: 0 | G44: ΔT
D45: Climate Change effect Tgem.zomer | E45: 1.7 | F45: 0 | G45: ΔT
D46: Climate Change effect Tgem.winter | E46: 1.4 | F46: 0 | G46: ΔT
D47: Climate Change effect Ezon.zomer | E47: =450 -> 450 | F47: 0 | G47: ΔP
D48: Climate Change effect Ezon.winter | E48: =220 -> 220 | F48: 0 | G48: ΔP

Sheet Invoer
E2: Apartement | F2: Index
B4: #Type | E4: Type apartement | F4: 5 | G4: =VLOOKUP(input_TypeApartement_value,Type,2) -> hoekappartement toren | L4: Parametrisch of het 1,2 of 3is (eenzijdig, hoek, gallerij) handmatig of het 1/2 of 4/5 (natuurlijk geventileerde kern = X-ventilatie in toren is)
B5: #Grootte | E5: Grootte | I5: 88 | J5: m²
B6: #Orient | E6: Orientatie | F6: 5 | G6: {=INDEX(Orientatie,F4,F6)} -> Z-W
B7: #Agevel | E7: Oppervlak buiten gevel | I7: 55 | J7: m²
B8: #Aglas | C8: %Glas | E8: Oppervlak glas in buitengevel | I8: =K8*input_OppervlakBuitenGevel_value -> 16.5 | J8: m² | K8: 0.3 | L8: mogelijk moeten we vooraf zelf een % glas opgeven als het nog niet in het model zit
B9: #Ugevel | E9: Uwaarde buitengevel | I9: 0.2 | J9: W/K.m²
B10: #Uglas | E10: Uwaarde glas | I10: 0.8 | J10: W/K.m²
B11: #ZTA_W | E11: ZTA zonder zonwering | I11: 0.35
B12: #ZTA_Z | E12: ZTA met zonwering | I12: 0.12
E13: Dak (J/N) | F13: 1
B14: #Dak_t | E14: Dak | F14: =IF(input_DakaAnwezigheid_value=0,1,HLOOKUP(scenario_selection, Scenario_Table, 2,FALSE)) -> 3 | G14: =VLOOKUP(F14,Dak,2) -> Groen | L14: Als er een dak is, handatig aangeven zwart/groen - parametrisch of apartmenet een dak heeft dus 1 of 2/3 parametrisch 2 f 3 handmatig
E15: =IF(F14>1,"Uwaarde","") -> Uwaarde | I15: =VLOOKUP(Dak_value,Dak_Uw,4) -> 0.18 | J15: W/K.m²
B16: #Massa | E16: Constructie wijze | F16: 3 | G16: =VLOOKUP(F16,Constructie,2) -> Hybride hout-beton
B17: #Hoogte | E17: Vloerhoogte | F17: 29.6 | J17: m
E20: Installatie gegevens
E21: Ventilatiesysteem | F21: =HLOOKUP(scenario_selection, Scenario_Table, 4,FALSE) -> 3 | G21: =VLOOKUP(F21,Ventilatie,2) -> Passive House
E22: Koude/warmte | F22: =HLOOKUP(scenario_selection, Scenario_Table, 5,FALSE) -> 3 | G22: =VLOOKUP(F22,Warmte,2) -> Stadsverwarming + Koelmachine
E23: Zonnecollector | F23: =HLOOKUP(scenario_selection, Scenario_Table, 6,FALSE) -> 3 | G23: =VLOOKUP(F23,Collector,2) -> Standaard | H23: ZonnecollectorOppervlak | I23: =IF(Zonnecollector_value>1,1,0) -> 1 | J23: =IF(F23>1,"m²","") -> m²
E24: Douche wtw | F24: =HLOOKUP(scenario_selection, Scenario_Table, 7,FALSE) -> 2 | G24: =VLOOKUP(F24,Douche,2) -> individueel
E25: CO2 regeling ventilatie | F25: =HLOOKUP(scenario_selection, Scenario_Table, 8,FALSE) -> 2 | G25: =IF(F25=1,"nee","ja") -> ja
E28: Buitenklimaat gegevens
E29: Locatie gegevens | F29: 2 | G29: =VLOOKUP(F29,Gegevens,2) -> bekend | H29: indien bekend | K29: Standaard klimaatjaar
E30: =IF(F$29=2,"Locatie gegevens Tgem","") -> Locatie gegevens Tgem | H30: =IF(F$29=2,"Δ","") -> Δ | I30: =0.4 -> 0.4 | J30: =IF($F$29=2,"°C","") -> °C | K30: 11.8 | L30: °C | M30: =(F29-1)*I30+K30 -> 12.2
B31: dT_Loc_Z | E31: =IF(F$29=2,"Locatie gegevens Tgem.zomer","") -> Locatie gegevens Tgem.zomer | H31: =IF(F$29=2,"Δ","") -> Δ | I31: =-0.2 -> -0.2 | J31: =IF($F$29=2,"°C","") -> °C | K31: 15.3 | L31: °C | M31: =(F29-1)*I31+K31 -> 15.1
B32: dT_Loc_W | E32: =IF(F$29=2,"Locatie gegevens Tgem.winter","") -> Locatie gegevens Tgem.winter | H32: =IF(F$29=2,"Δ","") -> Δ | I32: =0.6 -> 0.6 | J32: =IF($F$29=2,"°C","") -> °C | K32: =K30-(K31-K30) -> 8.3 | L32: °C | M32: =(F29-1)*I32+K32 -> 8.9
B33: dS_Loc_Z | E33: =IF(F$29=2,"Locatie gegevens Ezon.zomer","") -> Locatie gegevens Ezon.zomer | H33: =IF(F$29=2,"Δ","") -> Δ | I33: =100*750/1000 -> 75 | J33: =IF($F$29=2,"kWh/m²","") -> kWh/m² | K33: 700 | L33: kWh/m² | M33: =(F29-1)*I33+K33 -> 775
B34: dS_Loc_W | E34: =IF(F$29=2,"Locatie gegevensEzon.winter","") -> Locatie gegevensEzon.winter | H34: =IF(F$29=2,"Δ","") -> Δ | I34: =I33/3 -> 25 | J34: =IF($F$29=2,"kWh/m²","") -> kWh/m² | K34: 200 | L34: kWh/m² | M34: =(F29-1)*I34+K34 -> 225
E35: Climate Change effect | F35: 1 | G35: =VLOOKUP(F35,Gegevens,2) -> onbekend
E36: =IF(F$35=2,"Climate Change effect Tgem","") | H36: =IF(F$35=2,"Δ","") | I36: =(I37+I38)/2 -> 0.95 | J36: =IF($F$35=2,"°C","") | K36: 11.8 | L36: °C | M36: =(F35-1)*I36+LocatieGegevensTgem_value -> 12.2
B37: dT_CC_Z | E37: =IF(F$35=2,"Climate Change effect Tgem.zomer","") | H37: =IF(F$35=2,"Δ","") | I37: 0.7 | J37: =IF($F$35=2,"°C","") | K37: 15.3 | L37: °C | M37: =(F35-1)*I37+LocatieGegevensTgemZomer_value -> 15.1
B38: dT_CC_W | E38: =IF(F$35=2,"Climate Change effect Tgem.winter","") | H38: =IF(F$35=2,"Δ","") | I38: 1.2 | J38: =IF($F$35=2,"°C","") | K38: =K36-(K37-K36) -> 8.3 | L38: °C | M38: =(F35-1)*I38+LocatieGegevensTgemWinter_value -> 8.9
B39: dS_CC_Z | E39: =IF(F$35=2,"Climate Change effect Ezon.zomer","") | H39: =IF(F$35=2,"Δ","") | I39: 100 | J39: =IF($F$35=2,"kWh/m²","") | K39: 700 | L39: kWh/m² | M39: =(1+((F35-1)*I39)/K39)*LocatieGegevensEzonZomer_value -> 775
B40: dS_CC_W | E40: =IF(F$35=2,"Climate Change effect Ezon.winter","") | H40: =IF(F$35=2,"Δ","") | I40: 50 | J40: =IF($F$35=2,"kWh/m²","") | K40: 200 | L40: kWh/m² | M40: =(1+((F35-1)*I40)/K40)*LocatieGegevensEzonWinter_value -> 225
E41: Urban Heat Island | F41: 1 | G41: =VLOOKUP(F41,Gegevens,2) -> onbekend
E42: =IF(F$41=2,"Urban Heat Island Tgem","") | H42: =IF(F$41=2,"Δ","") | I42: 0.5 | J42: =IF($F$41=2,"°C","") | K42: 11.8 | L42: °C | M42: =(F41-1)*I42+ClimateChangeEffectTgem_value -> 12.2 | O42: ground level | Q42: per appartrment corrected for real height
B43: dT_UHI_Z | E43: =IF(F$41=2,"Urban Heat Island Tgem.zomer","") | H43: =IF(F$41=2,"Δ","") | I43: 0.7 | J43: =IF($F$41=2,"°C","") | K43: 15.3 | L43: °C | M43: =(F41-1)*I43+ClimateChangeEffectTgemZomer_value -> 15.1 | O43: ground level | Q43: per appartrment corrected for real height
B44: dT_UHI_W | E44: =IF(F$41=2,"Urban Heat Island Tgem.winter","") | H44: =IF(F$41=2,"Δ","") | I44: 0.2 | J44: =IF($F$41=2,"°C","") | K44: =K42-(K43-K42) -> 8.3 | L44: °C | M44: =(F41-1)*I44+ClimateChangeEffectTgemWinter_value -> 8.9 | O44: ground level | Q44: per appartrment corrected for real height
E45: Bezonning gevel | F45: 1 | G45: =VLOOKUP(F45,Gegevens,2) -> onbekend
B46: S_ber_Z | E46: =IF(F$45=2,"Bezonning gevel Ezon.zomer","") | I46: 600 | J46: =IF($F$45=2,"kWh/m²","") | K46: 700 | L46: kWh/m² | M46: =IF(F45=1,ClimateChangeEffectEzonZomer_value,BezonningGevelEzonZomer_value/K46*ClimateChangeEffectEzonZomer_value) -> 775 | O46: façade of main orienattion
...

Sheet Resultaten
X3: 1 | Y3: kWh | Z3: =3600/1000 -> 3.6 | AA3: MJ
X4: 1 | Y4: MJ | Z4: =1/Z3 -> 0.27777778 | AA4: kWh
F5: Bewoners | G5: =HLOOKUP(Invoer!$I$5,Bezetting,6) -> 2.2257785 | H5: #
F6: Bezetting | G6: =HLOOKUP(Invoer!$I$5,Bezetting,7) -> 1.9335882 | H6: # | N6: 1 | O6: GJ stadsverwaming | Q6: 1 | R6: kg CO2 | X6: 1 | Y6: kWh | Z6: 0.42 | AA6: kg CO2 | AB6: 2025
F7: Gebruiksuren | G7: =HLOOKUP(Invoer!$I$5,Bezetting,8) -> 18.290912 | H7: uur | X7: 1 | Y7: GJ | Z7: 37.44 | AA7: kg CO2 | AB7: 2023
F8: Totaal energie gebruik [e] | G8: =G9+G16 -> 3740.5491 | H8: kWh/j | K8: CO2 equivalente kWh | P8: kWh elektrisch | U8: GJ stadsverwarming
F9: Gebouw | G9: =J31+J36+J49+J67+J94 -> 2308.4045 | H9: kWh/j | K9: =G9/Invoer!$I$5 -> 26.231869 | L9: kWh/j/m² | M9: Gebouw_per_sqm | X9: 1 | Y9: GJ = | Z9: =1000*Z4 -> 277.77778 | AA9: kWh
F10: Warmtapwater | I10: =J31 -> 414.77358 | J10: kWh/j | K10: =I10/Invoer!$I$5 -> 4.7133361 | L10: kWh[e] | M10: Warmtapwater_per_sqm | O10: =input_GrootteApartement_value*Resultaten!Q10 -> 0 | P10: kWh/app | Q10: =VLOOKUP(KoudeWarmte_value,inkoop_tabel,2)*$K$10 -> 0 | R10: kWh/j.m² | S10: =input_GrootteApartement_value*Resultaten!U10 -> 4.6529087 | T10: GJ/app.j | U10: =VLOOKUP(KoudeWarmte_value,inkoop_tabel,4)*$K$10 -> 0.052873963 | V10: MJ/j.m² | X10: 1 | Y10: GJ sv ~ | Z10: =Z7/Z6 -> 89.142857 | AA10: kWh based on CO2
F11: Verlichting | I11: =J36 -> 256.04413 | J11: kWh/j | K11: =I11/Invoer!$I$5 -> 2.9095924 | M11: Verlichting_per_sqm
F12: Ventilatie | I12: =J49 -> 594.19834 | J12: kWh/j | K12: =I12/Invoer!$I$5 -> 6.7522539 | M12: Ventilatie_per_sqm
F13: Koeling | I13: =J67 -> 91.98594 | J13: kWh/j | K13: =I13/Invoer!$I$5 -> 1.0452948 | M13: Koeling_per_sqm
F14: Verwarming | I14: =J94 -> 951.40246 | J14: kWh/j | K14: =I14/Invoer!$I$5 -> 10.811392 | L14: kWh[e] | M14: Verwarming_per_sqm | O14: =input_GrootteApartement_value*Resultaten!Q14 -> 0 | P14: kWh/app | Q14: =VLOOKUP(KoudeWarmte_value,inkoop_tabel,3)*$K$14 -> 0 | R14: kWh/j.m² | S14: =input_GrootteApartement_value*Resultaten!U14 -> 10.672784 | T14: GJ/app.j | U14: =VLOOKUP(KoudeWarmte_value,inkoop_tabel,5)*$K$14 -> 0.12128164 | V14: MJ/j.m² | X14: 1 | Y14: GJ | Z14: =1000/32 -> 31.25 | AA14: m3 aardgas
X15: 1 | Y15: m3 HR | Z15: =64/(1000/32) -> 2.048 | AA15: kg CO2
F16: Gebruiker | G16: =J21+J23 -> 1432.1447 | H16: kWh/j | K16: =G16/Invoer!$I$5 -> 16.274371 | L16: kWh/j/m² | M16: Gebruiker_per_sqm
F17: Wasmachine, droger,vaatwasser | I17: =J21 -> 721.42977 | J17: kWh/j | K17: =I17/Invoer!$I$5 -> 8.1980655 | M17: Wasmachine, droger,vaatwasser_per_sqm
F18: Media apparatuur, overige | I18: =J23 -> 710.71488 | J18: kWh/j | K18: =I18/Invoer!$I$5 -> 8.0763055 | M18: Media apparatuur, overige__per_sqm
F21: Wasmachine, vaatwasser, droger | J21: =Coeefficienten!F6+Coeefficienten!F8*(Resultaten!G5-1)^0.5 -> 721.42977 | K21: kWh/j | S21: =IF((S10+S14)>0,(S14+S10)*Z14,0) -> 478.9279 | T21: m3 aardgas equivalent (SV equivalenten)
S22: =S21*Z15 -> 980.84434 | T22: kg CO2 [HR ketel]
F23: Media apparatuur, overige | J23: =Coeefficienten!F9+Coeefficienten!F11*(Resultaten!G5-1)^0.5 -> 710.71488 | K23: kWh/j | S23: =S22/Z6 -> 2335.3437 | T23: kWh[eq] e inkoop tov van | W23: =(output_TotaalEnergieVerwarming_value+output_TotaalEnergieWarmtapwater_value) -> 1366.176 | X23: kWh
F25: Warmtapwater
F26: Warmtapwater [basis] | G26: =Coeefficienten!F13+Coeefficienten!F14*(Resultaten!G5)^0.95 -> 1910.7945 | H26: kWh/j | I26: warmte
F27: reductie douche wtw | G27: =VLOOKUP(Invoer!F24,douche_reductie,3)*G26 -> 573.23835 | H27: kWh/j | I27: warmte
F28: reductie zonthermisch | G28: =VLOOKUP(Invoer!F23,Zon_reductie,3)*Invoer!I23 -> 350 | H28: kWh/j | I28: warmte
F30: Warmtapwater warmte | G30: =G26-G27-G28 -> 987.55614 | H30: kWh/j | I30: w | N30: =G30*3.6/35 -> 101.5772 | O30: m3 aardgas eq.
F31: Warmtapwater elektra | I31: e | J31: =G30/VLOOKUP(Invoer!F22,COP_,3) -> 414.77358 | K31: kWh/j
F33: Verlichting
F34: Verlichting[basis] | G34: =Invoer!I5*(Coeefficienten!F64+Coeefficienten!F65*(50/Invoer!I5)^0.25)+Coeefficienten!F66*(Resultaten!G5-1) -> 402.41191 | H34: kWh/j
F35: F[DF] | G35: =+(1-Coeefficienten!H82) -> 0.63627374
F36: Verlichting elektra | J36: =G35*G34 -> 256.04413 | K36: kWh/j
F39: Ventilatie
F40: debiet | G40: =HLOOKUP(Invoer!$I$5,ventilatie_tabel,11) -> 30.703487 | H40: l/s.gem | I40: met CO2
G41: =HLOOKUP(Invoer!$I$5,ventilatie_tabel,4) -> 76.5 | H41: l/s.max | I41: zonder CO2
F42: Vormfactor | G42: =Uren_factor -> 1.4822531
F43: Debiet_calc | G43: =IF(Invoer!F25=1,Resultaten!G41,MIN(G41,Resultaten!G42*G40)) -> 45.510339 | H43: l/s
F44: dPmin | G44: =VLOOKUP(Invoer!F21,Vent_coef,3) -> 150 | H44: Pa
F45: dPmax | G45: =VLOOKUP(Invoer!F21,Vent_coef,4) -> 750 | H45: Pa
F46: dPgem | G46: =G44+(G43/G41)*G45 -> 596.17979 | H46: Pa
F47: Gebruikstijd | G47: =24*365 -> 8760 | H47: uur
F48: Gem.vermogen | G48: =G43/1000*G46/0.4 -> 67.830861 | H48: Wgem.
F49: Ventilatie | J49: =G48*G47/1000 -> 594.19834 | K49: kWh/j
...

Sheet Tabellen
B2: Index | G2: Orientatie
C3: Apartement type | F3: index | N3: hand | P3: parameter
B4: 1 | C4: eenzijdig toren | D4: Avl[m²] | I4: Appartment not on a corner in a tower with closed core | N4: open/closed | P4: tower/gallery - fi tower corner/no corner
B5: 2 | C5: tweezijdig toren (kern) | D5: Avl[m²] | I5: Appartment not on a corner in a tower with open core | N5: open/closed
B6: 3 | C6: gallerij flat | D6: Avl[m²]
B7: 4 | C7: hoek en tweezijdig toren | D7: Avl[m²] | I7: Appartment on a corner in a tower with open core | N7: open/closed
B8: 5 | C8: hoekappartement toren | D8: Avl[m²] | I8: Appartment on a corner in a tower with closed core | N8: open/closed
C11: Orientatie | D11: 1 | E11: 2 | F11: 3 | G11: 4 | H11: 5 | I11: 5 | J11: 6 | K11: 7 | L11: index orientatie
B12: 1 | C12: eenzijdig toren | D12: N | E12: NO | F12: O | G12: ZO | H12: Z | I12: ZW | J12: W | K12: NW | L12: opmerking: eenzijdig apartement orientatie is buitengevel
B13: 2 | C13: tweezijdig toren (kern) | D13: N | E13: NO | F13: O | G13: ZO | H13: Z | I13: ZW | J13: W | K13: NW | L13: opmerking: eenzijdig apartement orientatie is buitengevel
B14: 3 | C14: gallerij flat | D14: N | E14: NO | F14: O | G14: ZO | H14: Z | I14: ZW | J14: W | K14: NW | L14: opmerking: tweezijdig tegenoverliggend/gallerij apartement orientatie is voorgevel, = niet gallerij zijde
B15: 4 | C15: hoekappartement toren | D15: N-O | E15: NO-ZO | F15: O-Z | G15: ZO-ZW | H15: Z-W | I15: ZW-NW | J15: W-N | K15: NW-NO | L15: opmerking: tweezijdig haaks/torenj apartement orientatie is orientatie van de hoek tussen de 2-voorgevel
B16: 5 | C16: hoek en tweezijdig toren | D16: N-O | E16: NO-ZO | F16: O-Z | G16: ZO-ZW | H16: Z-W | I16: ZW-NW | J16: W-N | K16: NW-NO | L16: opmerking: tweezijdig haaks/torenj apartement orientatie is orientatie van de hoek tussen de 2-voorgevel
C19: Gevel oppervlak | D19: N | E19: NO | F19: O | G19: ZO | H19: Z | I19: ZW | J19: W | K19: NW | P19: Gevel oppervlak | R19: %glas correctie
B20: 1 | C20: eenzijdig toren | D20: Age[m²] | E20: Age[m²] | F20: Age[m²] | G20: Age[m²] | H20: Age[m²] | I20: Age[m²] | J20: Age[m²] | K20: Age[m²] | M20: U[W/m².K] | O20: 1 | P20: eenzijdig toren | R20: 1
B21: 2 | C21: tweezijdig toren (kern) | D21: Age[m²] | E21: Age[m²] | F21: Age[m²] | G21: Age[m²] | H21: Age[m²] | I21: Age[m²] | J21: Age[m²] | K21: Age[m²] | M21: U[W/m².K] | O21: 2 | P21: tweezijdig toren (kern) | R21: 1
B22: 3 | C22: gallerij flat | D22: Age[m²] | E22: Age[m²] | F22: Age[m²] | G22: Age[m²] | H22: Age[m²] | I22: Age[m²] | J22: Age[m²] | K22: Age[m²] | M22: U[W/m².K] | O22: 3 | P22: gallerij flat | R22: 0.8
B23: 4 | C23: hoekappartement toren | D23: Age[m²] | E23: Age[m²] | F23: Age[m²] | G23: Age[m²] | H23: Age[m²] | I23: Age[m²] | J23: Age[m²] | K23: Age[m²] | M23: U[W/m².K] | O23: 4 | P23: hoekappartement toren | R23: =(10/36)/0.4*0.9 -> 0.625
B24: 5 | C24: hoek en tweezijdig toren | D24: Age[m²] | E24: Age[m²] | F24: Age[m²] | G24: Age[m²] | H24: Age[m²] | I24: Age[m²] | J24: Age[m²] | K24: Age[m²] | M24: U[W/m².K] | O24: 5 | P24: hoek en tweezijdig toren | R24: =R23 -> 0.625
D25: N-O | E25: NO-ZO | F25: O-Z | G25: ZO-ZW | H25: Z-W | I25: ZW-NW | J25: W-N | K25: NW-NO
C28: Orientatie & gevel oppervlak | D28: N | E28: NO | F28: O | G28: ZO | H28: Z | I28: ZW | J28: W | K28: NW
B29: 1 | C29: eenzijdig toren | D29: Agl[m²] | E29: Agl[m²] | F29: Agl[m²] | G29: Agl[m²] | H29: Agl[m²] | I29: Agl[m²] | J29: Agl[m²] | K29: Agl[m²] | M29: U[W/m².K] | N29: ZTA[-zonw] | O29: ZTA[+zonw]
B30: 2 | C30: tweezijdig toren (kern) | D30: Agl[m²] | E30: Agl[m²] | F30: Agl[m²] | G30: Agl[m²] | H30: Agl[m²] | I30: Agl[m²] | J30: Agl[m²] | K30: Agl[m²] | M30: U[W/m².K] | N30: ZTA[-zonw] | O30: ZTA[+zonw]
B31: 3 | C31: gallerij flat | D31: Agl[m²] | E31: Agl[m²] | F31: Agl[m²] | G31: Agl[m²] | H31: Agl[m²] | I31: Agl[m²] | J31: Agl[m²] | K31: Agl[m²] | M31: U[W/m².K] | N31: ZTA[-zonw] | O31: ZTA[+zonw]
B32: 5 | C32: hoekappartement toren | D32: Agl[m²] | E32: Agl[m²] | F32: Agl[m²] | G32: Agl[m²] | H32: Agl[m²] | I32: Agl[m²] | J32: Agl[m²] | K32: Agl[m²] | M32: U[W/m².K] | N32: ZTA[-zonw] | O32: ZTA[+zonw]
B33: 6 | C33: hoek en tweezijdig toren | D33: Agl[m²] | E33: Agl[m²] | F33: Agl[m²] | G33: Agl[m²] | H33: Agl[m²] | I33: Agl[m²] | J33: Agl[m²] | K33: Agl[m²] | M33: U[W/m².K] | N33: ZTA[-zonw] | O33: ZTA[+zonw]
D34: N-O | E34: NO-ZO | F34: O-Z | G34: ZO-ZW | H34: Z-W | I34: ZW-NW | J34: W-N | K34: NW-NO
C35: Dak
B36: 1 | C36: Geen dak
B37: 2 | C37: Zwart | D37: U[W/m².K]
B38: 3 | C38: Groen | D38: U[W/m².K]
F40: Isolatie concepten
C41: Ventilatie systeem | F41: Uwand | G41: Uraam | H41: Udak | I41: ZTAstd | J41: ZTAzonw | K41: Aglas
B42: 1 | C42: Nat. toevoer + mech. Afzuiging | E42: 1 | F42: 0.3 | G42: 1.2 | H42: 0.25 | I42: 0.35 | J42: 0.1 | K42: 0.4
B43: 2 | C43: Nat toevoer met indirecte ww | E43: 2 | F43: 0.05 | G43: 1.2 | H43: 0.25 | I43: 0.35 | J43: 0.1 | K43: 0.4
B44: 3 | C44: Passive House | E44: 3 | F44: 0.2 | G44: 0.8 | H44: 0.2 | I44: 0.3 | J44: 0.05 | K44: 0.3
B45: 4 | C45: Balans met WTW | E45: 4 | F45: 0.35 | G45: 1 | H45: 0.25 | I45: 0.35 | J45: 0.12 | K45: 0.7
C48: Constructie wijze
B49: 1 | C49: Volledig hout
B50: 2 | C50: Hyrbide hout-staal
...

Sheet Coeefficienten
E3: Energie basis parameters
E5: Gebruikers energie
E6: Wasmachine, vaatwasser, droger | F6: 500 | G6: kWh/jaar | I6: basis per huishouden
F7: 0 | G7: kWh/jaar | I7: extra persoon ^,95
F8: 200 | G8: kWh/jaar | I8: extra persoon ^,5
E9: Media apparatuur, overige | F9: 600 | G9: kWh/jaar | I9: basis per huishouden
F10: 0 | G10: kWh/jaar | I10: extra persoon ^,95
F11: 100 | G11: kWh/jaar | I11: extra persoon ^,5
E13: Warmtapwater [warmtevraag] | F13: 200 | G13: kWh/jaar | I13: basis per huishouden
F14: 800 | G14: kWh/jaar | I14: per persoon ^,95
F15: 0 | G15: kWh/jaar | I15: per persoon ^,5
O16: Tabel kWh[e] en GJ[sv]
J17: equivalente COP stadsverwarming | O17: e | Q17: sv
F18: COP[tw] | G18: COP[w] | H18: COP[k] | K18: % SV | O18: TW | P18: W | Q18: TW | R18: W
B19: COP tw,w,k | C19: #Type | D19: 1 | E19: Warmtepomp lucht | F19: 2.75 | G19: 3.5 | H19: 3.5 | N19: 1 | O19: 1 | P19: 1 | Q19: 0 | R19: 0
D20: 2 | E20: Warmtepomp WKO | F20: 4 | G20: 6 | H20: 10 | N20: =N19+1 -> 2 | O20: 1 | P20: 1 | Q20: 0 | R20: 0
D21: 3 | E21: Stadsverwarming + Koelmachine | F21: =J21 -> 2.3809524 | G21: =J21 -> 2.3809524 | H21: =H19 -> 3.5 | J21: =(Resultaten!Z10/Resultaten!Z7) -> 2.3809524 | N21: =N20+1 -> 3 | O21: 0 | P21: 0 | Q21: =1/Resultaten!Z10 -> 0.011217949 | R21: =Q21 -> 0.011217949
D22: 4 | E22: Stadsverwarming Tapwater + warmtepomp | F22: =J22 -> 2.3809524 | G22: =G19 -> 3.5 | H22: =H19 -> 3.5 | J22: =J21 -> 2.3809524 | N22: =N21+1 -> 4 | O22: 0 | P22: 0 | Q22: =Q21 -> 0.011217949 | R22: =R21 -> 0.011217949
D23: 5 | E23: SV + warmtepomp - Tafhankelijk | F23: =J23 -> 2.3809524 | G23: =6.5*(1-K23)+K23*J23 -> 5.4702381 | H23: =H22 -> 3.5 | J23: =J22 -> 2.3809524 | K23: 0.25 | N23: =N22+1 -> 5 | O23: 1 | P23: =1-K23 -> 0.75 | Q23: =Q22 -> 0.011217949 | R23: =Q23*K23 -> 0.0028044872
E25: Zonthermische panelen
D26: 1 | E26: geen | F26: 0 | G26: kWh/m² reductie
D27: 2 | E27: PVT | F27: 300 | G27: kWh/m² reductie
D28: 3 | E28: Standaard | F28: 350 | G28: kWh/m² reductie
D29: 4 | E29: Vacuum | F29: 550 | G29: kWh/m² reductie
E31: Douche wtw
D32: 1 | E32: geen | F32: 0 | G32: reductie
D33: 2 | E33: individueel | F33: 0.3 | G33: reductie
D34: 3 | E34: collectief | F34: 0.4 | G34: reductie
E36: Ventilator energie
E37: Systeem | F37: min | G37: max | I37: η[wtw]
D38: 1 | E38: Nat. toevoer + mech. Afzuiging | F38: 20 | G38: 100 | H38: Pa | I38: 0
D39: 2 | E39: Nat toevoer met indirecte ww | F39: =F38 -> 20 | G39: =G38 -> 100 | H39: Pa | I39: 0.4
D40: 3 | E40: Passive House | F40: 150 | G40: 750 | H40: Pa | I40: 0.9
D41: 4 | E41: Balans met WTW | F41: 100 | G41: 600 | H41: Pa | I41: 0.8
E43: Coeffcient max draai uren - type | F43: {=INDEX(F45:M49,input_TypeApartement_value,input_Orientatie_value)} -> 1.4822531
F44: N | G44: NO | H44: O | I44: ZO | J44: Z | K44: ZW | L44: W | M44: NW | O44: zon | P44: spui
D45: 1 | E45: eenzijdig toren | F45: 1 | G45: 1.05 | H45: 1.2 | I45: 1.25 | J45: 1.5 | K45: 1.75 | L45: 1.5 | M45: 1.2 | O45: =AVERAGE(F45:M45) -> 1.30625 | P45: 1.4
D46: 2 | E46: tweezijdig toren (kern) | F46: 1 | G46: =((G45-1)/1.2)^4+1 -> 1.000003 | H46: =((H45-1)/1.2)^4+1 -> 1.0007716 | I46: =((I45-1)/1.2)^4+1 -> 1.0018838 | J46: =((J45-1)/1.2)^4+1 -> 1.0301408 | K46: =((K45-1)/1.2)^4+1 -> 1.1525879 | L46: =((L45-1)/1.2)^4+1 -> 1.0301408 | M46: =((M45-1)/1.2)^4+1 -> 1.0007716 | O46: =AVERAGE(F46:M46) -> 1.0270374 | P46: 0.9
D47: 3 | E47: gallerij flat | F47: 0.7 | G47: =F47+0.025 -> 0.725 | H47: =G47+0.025 -> 0.75 | I47: =H47+0.025 -> 0.775 | J47: =I47+0.025 -> 0.8 | K47: =J47+0.025 -> 0.825 | L47: =K47+0.025 -> 0.85 | M47: =(L47+F47)/2 -> 0.775 | O47: =AVERAGE(F47:M47) -> 0.775 | P47: 0.9
D48: 4 | E48: hoekappartement toren | F48: 1.1 | G48: 1.2 | H48: 1.5 | I48: 1.75 | J48: 2 | K48: 1.5 | L48: 1.25 | M48: 1.1 | O48: =AVERAGE(F48:M48) -> 1.425 | P48: 1.2
...

Sheet Basis waarden en tabellen
C3: Demography NL
D4: categorien | F4: % | G4: # | J4: /hh | P4: 20 - 30 | Q4: 30 - 55 | R4: > 55
D5: van | E5: tot | G5: x 1000 | I5: x 1000 | J5: #1 | O5: uur/dag p.p. | P5: 13 | Q5: 15 | R5: 18 | S5: per persoon
D6: 55 | E6: 105 | F6: 0.34543942 | G6: 6230 | I6: =G6 -> 6230 | J6: 1.5 | K6: 4153.3333 | O6: slaap | P6: 8 | Q6: 9 | R6: 9
D7: 30 | E7: 55 | F7: 0.31699473 | G7: 5717 | I7: =G7+G9 -> 9434 | J7: 3.5 | K7: 2695.4286 | O7: non-slaap | P7: 5 | Q7: 6 | R7: 9
D8: 20 | E8: 30 | F8: 0.13146659 | G8: 2371 | I8: =G8 -> 2371 | J8: 1.4 | K8: 1693.5714 | O8: gelijktijdig non-slaap | P8: 0.7 | Q8: 0.6 | R8: 0.85
D9: 0 | E9: 20 | F9: 0.20609925 | G9: 3717 | O9: gebruiksuren | P9: =P6+P7/P8 -> 15.142857 | Q9: =Q6+Q7/Q8 -> 19 | R9: =R6+R7/R8 -> 19.588235 | S9: #2
J10: =SUMPRODUCT(K6:K8,J6:J8)/F12 -> 2.1 | K10: 8542.3333 | O10: gemiddelde bezetting | P10: =(P6*J8+P7*P8*J8)/P5 -> 1.2384615 | Q10: =(Q6*J7+Q7*Q8*J7)/Q5 -> 2.94 | R10: =(R6*J6+R7*R8*J6)/R5 -> 1.3875 | S10: #3
O11: gemiddelde grootte huishoudens | S11: 2.1
E12: aantal huishoudens | F12: =F13/G12 -> 8588.0952 | G12: 2.1
E13: aantal mensen | F13: =SUM(G6:G9) -> 18035
D16: Bezetting
C17: Apartement grootte | D17: 40 | E17: =D17+5 -> 45 | F17: =E17+5 -> 50 | G17: =F17+5 -> 55 | H17: =G17+5 -> 60 | I17: =H17+5 -> 65 | J17: =I17+5 -> 70 | K17: =J17+5 -> 75 | L17: =K17+5 -> 80 | ... Z17: =Y17+5 -> 150
C18: Demography
C19: > 55 | D19: =1-D20-D21 -> 0.15 | E19: =1-E20-E21 -> 0.125 | F19: =1-F20-F21 -> 0.1 | G19: =1-G20-G21 -> 0.1964876 | H19: =1-H20-H21 -> 0.26388889 | I19: =1-I20-I21 -> 0.31079882 | J19: =1-J20-J21 -> 0.34285714 | K19: =1-K20-K21 -> 0.36388889 | ... Z19: =1-Z20-Z21 -> 0.22222222
C20: 30-55 | D20: 0.15 | E20: =D20+0.025 -> 0.175 | F20: =E20+0.025 -> 0.2 | G20: =F20+0.025 -> 0.225 | H20: =G20+0.025 -> 0.25 | I20: =H20+0.025 -> 0.275 | J20: =I20+0.025 -> 0.3 | K20: =J20+0.025 -> 0.325 | L20: =K20+0.025 -> 0.35 | ... Z20: =Y20+0.025 -> 0.7
C21: 20-30 | D21: 0.7 | E21: =$D$21*MIN(1,(50/E17)^2) -> 0.7 | F21: =$D$21*MIN(1,(50/F17)^2) -> 0.7 | G21: =$D$21*MIN(1,(50/G17)^2) -> 0.5785124 | H21: =$D$21*MIN(1,(50/H17)^2) -> 0.48611111 | I21: =$D$21*MIN(1,(50/I17)^2) -> 0.41420118 | J21: =$D$21*MIN(1,(50/J17)^2) -> 0.35714286 | K21: =$D$21*MIN(1,(50/K17)^2) -> 0.31111111 | L21: =$D$21*MIN(1,(50/L17)^2) -> 0.2734375 | ... Z21: =$D$21*MIN(1,(50/Z17)^2) -> 0.077777778
A22: #B1 | B22: #1 | C22: Aantal bewoners | D22: =SUMPRODUCT(D19:D21,$J$6:$J$8) -> 1.73 | E22: =SUMPRODUCT(E19:E21,$J$6:$J$8) -> 1.78 | F22: =SUMPRODUCT(F19:F21,$J$6:$J$8) -> 1.83 | G22: =SUMPRODUCT(G19:G21,$J$6:$J$8) -> 1.8921488 | H22: =SUMPRODUCT(H19:H21,$J$6:$J$8) -> 1.9513889 | I22: =SUMPRODUCT(I19:I21,$J$6:$J$8) -> 2.0085799 | J22: =SUMPRODUCT(J19:J21,$J$6:$J$8) -> 2.0642857 | K22: =SUMPRODUCT(K19:K21,$J$6:$J$8) -> 2.1188889 | ... Z22: =SUMPRODUCT(Z19:Z21,$J$6:$J$8) -> 2.8922222
A23: #B2 | B23: #3 | C23: Gemiddelde bezetting | D23: =D19*$R$10+D20*$Q$10+D21*$P$10 -> 1.5160481 | E23: =E19*$R$10+E20*$Q$10+E21*$P$10 -> 1.5548606 | F23: =F19*$R$10+F20*$Q$10+F21*$P$10 -> 1.5936731 | G23: =G19*$R$10+G20*$Q$10+G21*$P$10 -> 1.6505919 | H23: =H19*$R$10+H20*$Q$10+H21*$P$10 -> 1.7031757 | I23: =I19*$R$10+I20*$Q$10+I21*$P$10 -> 1.7527056 | J23: =J19*$R$10+J20*$Q$10+J21*$P$10 -> 1.800022 | K23: =K19*$R$10+K20*$Q$10+K21*$P$10 -> 1.845695 | ... Z23: =Z19*$R$10+Z20*$Q$10+Z21*$P$10 -> 2.4626581
A24: #B3 | B24: #2 | C24: Gebruiksuren | D24: =$P$9*D21+$Q$9*D20+$R$9*D19 -> 16.388235 | E24: =$P$9*E21+$Q$9*E20+$R$9*E19 -> 16.373529 | F24: =$P$9*F21+$Q$9*F20+$R$9*F19 -> 16.358824 | G24: =$P$9*G21+$Q$9*G20+$R$9*G19 -> 16.884176 | H24: =$P$9*H21+$Q$9*H20+$R$9*H19 -> 17.280229 | I24: =$P$9*I21+$Q$9*I20+$R$9*I19 -> 17.58519 | J24: =$P$9*J21+$Q$9*J20+$R$9*J19 -> 17.82413 | K24: =$P$9*K21+$Q$9*K20+$R$9*K19 -> 18.014052 | ... Z24: =$P$9*Z21+$Q$9*Z20+$R$9*Z19 -> 18.830719
C27: Ventilator energie
E28: van | F28: 0 | G28: =F29 -> 85 | H28: =G29 -> 125 | I28: m²
E29: tot | F29: 85 | G29: 125 | H29: 200 | I29: m²
C30: keuken | D30: 20.833333 | E30: l/s | F30: 1 | G30: 1 | H30: 1
C31: badkamer | D31: 13.888889 | E31: l/s | F31: 1 | G31: 1 | H31: 2
C32: toilet | D32: 6.9444444 | E32: l/s | F32: 1 | G32: 2 | H32: 2
F33: 41.666667 | G33: 48.611111 | H33: 62.5 | I33: #4
C34: vloer | D34: 0.9 | E34: l/s.m² | F34: #5
C35: minimaal debiet | D35: 7 | E35: l/s | F35: #6
D37: Ventilatie_tabel
C38: Apartement grootte | D38: 40 | E38: =D38+5 -> 45 | F38: =E38+5 -> 50 | G38: =F38+5 -> 55 | H38: =G38+5 -> 60 | I38: =H38+5 -> 65 | J38: =I38+5 -> 70 | K38: =J38+5 -> 75 | L38: =K38+5 -> 80 | ... Z38: =Y38+5 -> 150
B39: #4,#6 | C39: minimaal debiet [l/s] | D39: =$D$35*HLOOKUP(D38,$F$28:$H$33,5) -> 7 | E39: =$D$35*HLOOKUP(E38,$F$28:$H$33,5) -> 7 | F39: =$D$35*HLOOKUP(F38,$F$28:$H$33,5) -> 7 | G39: =$D$35*HLOOKUP(G38,$F$28:$H$33,5) -> 7 | H39: =$D$35*HLOOKUP(H38,$F$28:$H$33,5) -> 7 | I39: =$D$35*HLOOKUP(I38,$F$28:$H$33,5) -> 7 | J39: =$D$35*HLOOKUP(J38,$F$28:$H$33,5) -> 7 | K39: =$D$35*HLOOKUP(K38,$F$28:$H$33,5) -> 7 | ... Z39: =$D$35*HLOOKUP(Z38,$F$28:$H$33,5) -> 14
B40: Bezetting | C40: gemiddeld [l/s] | D40: =D23*50/3.6 -> 21.056223 | E40: =E23*50/3.6 -> 21.595286 | F40: =F23*50/3.6 -> 22.134348 | G40: =G23*50/3.6 -> 22.924888 | H40: =H23*50/3.6 -> 23.655219 | I40: =I23*50/3.6 -> 24.343133 | J40: =J23*50/3.6 -> 25.000305 | K40: =K23*50/3.6 -> 25.634652 | ... Z40: =Z23*50/3.6 -> 34.203585
B41: #4, #5 | C41: maximum l/s] | D41: =MAX($D$34*D38,HLOOKUP(D38,$F$28:$H$33,6)) -> 41.666667 | E41: =MAX($D$34*E38,HLOOKUP(E38,$F$28:$H$33,6)) -> 41.666667 | F41: =MAX($D$34*F38,HLOOKUP(F38,$F$28:$H$33,6)) -> 45 | G41: =MAX($D$34*G38,HLOOKUP(G38,$F$28:$H$33,6)) -> 49.5 | H41: =MAX($D$34*H38,HLOOKUP(H38,$F$28:$H$33,6)) -> 54 | I41: =MAX($D$34*I38,HLOOKUP(I38,$F$28:$H$33,6)) -> 58.5 | J41: =MAX($D$34*J38,HLOOKUP(J38,$F$28:$H$33,6)) -> 63 | K41: =MAX($D$34*K38,HLOOKUP(K38,$F$28:$H$33,6)) -> 67.5 | ... Z41: =MAX($D$34*Z38,HLOOKUP(Z38,$F$28:$H$33,6)) -> 135
C43: Gebruikstijd/dag/basis
B44: Bezetting | C44: minimum [uur/dag] | D44: =24-D45-D46 -> 7.6117647 | E44: =24-E45-E46 -> 7.6264706 | F44: =24-F45-F46 -> 7.6411765 | G44: =24-G45-G46 -> 7.115824 | H44: =24-H45-H46 -> 6.7197712 | I44: =24-I45-I46 -> 6.4148103 | J44: =24-J45-J46 -> 6.1758703 | K44: =24-K45-K46 -> 5.9859477 | ... Z44: =24-Z45-Z46 -> 5.169281
B45: Bezetting | C45: gemiddeld [uur/dag] | D45: =D24-D46 -> 13.793235 | E45: =E24-E46 -> 13.703529 | F45: =F24-F46 -> 13.613824 | G45: =G24-G46 -> 14.045953 | H45: =H24-H46 -> 14.353145 | I45: =I24-I46 -> 14.57232 | J45: =J24-J46 -> 14.727701 | K45: =K24-K46 -> 14.835719 | ... Z45: =Z24-Z46 -> 14.492386
B46: Bezetting | C46: maximum [uur/dag] | D46: =D22*1.5 -> 2.595 | E46: =E22*1.5 -> 2.67 | F46: =F22*1.5 -> 2.745 | G46: =G22*1.5 -> 2.8382231 | H46: =H22*1.5 -> 2.9270833 | I46: =I22*1.5 -> 3.0128698 | J46: =J22*1.5 -> 3.0964286 | K46: =K22*1.5 -> 3.1783333 | ... Z46: =Z22*1.5 -> 4.3383333
A48: #V1 | B48: Intern | C48: Gemiddeldedebiet [l/s] | D48: =(D39*D44+D40*D45+D41*D46)/24 -> 18.8267 | E48: =(E39*E44+E40*E45+E41*E46)/24 -> 19.190289 | F48: =(F39*F44+F40*F45+F41*F46)/24 -> 19.931098 | G48: =(G39*G44+G40*G45+G41*G46)/24 -> 21.346029 | H48: =(H39*H44+H40*H45+H41*H46)/24 -> 22.692821 | I48: =(I39*I44+I40*I45+I41*I46)/24 -> 23.99552 | J48: =(J39*J44+J40*J45+J41*J46)/24 -> 25.270963 | K48: =(K39*K44+K40*K45+K41*K46)/24 -> 26.531151 | ... Z48: =(Z39*Z44+Z40*Z45+Z41*Z46)/24 -> 48.072353
A49: #V2 | B49: Intern | C49: Gemiddeld ΔP[min]-[max] | D49: =(D40-D39)/(D41-D39)/2+((D40-D39)/(D41-D39)/2)^1.3 -> 0.3283383 | E49: =(E40-E39)/(E41-E39)/2+((E40-E39)/(E41-E39)/2)^1.3 -> 0.34241102 | F49: =(F40-F39)/(F41-F39)/2+((F40-F39)/(F41-F39)/2)^1.3 -> 0.32185046 | G49: =(G40-G39)/(G41-G39)/2+((G40-G39)/(G41-G39)/2)^1.3 -> 0.30071027 | H49: =(H40-H39)/(H41-H39)/2+((H40-H39)/(H41-H39)/2)^1.3 -> 0.28260954 | I49: =(I40-I39)/(I41-I39)/2+((I40-I39)/(I41-I39)/2)^1.3 -> 0.26704819 | J49: =(J40-J39)/(J41-J39)/2+((J40-J39)/(J41-J39)/2)^1.3 -> 0.25358807 | K49: =(K40-K39)/(K41-K39)/2+((K40-K39)/(K41-K39)/2)^1.3 -> 0.24186651 | ... Z49: =(Z40-Z39)/(Z41-Z39)/2+((Z40-Z39)/(Z41-Z39)/2)^1.3 -> 0.12312254
...

Sheet Parameter Overview
B3: Parameter Name in Excel | C3: Parameter Name in Speckle | D3: Used by grasshopper (y/n) | E3: Used by Excel Currently (y/n) | F3: Available on Speckle unit Model (y/n)
B4: Type apartement | C4: topology, access_type | D4: y | E4: y | F4: y
B5: Orientatie | C5: orientation | D5: y | E5: y | F5: y
B6: Grootte | C6: BVO_woning | D6: y | E6: y | F6: y
B7: Oppervlak buiten gevel | C7: exterior_facade_area_m2 | D7: n | E7: n | F7: y
B8: Oppervlak glas in buitengevel | C8: by excell not Grasshopper | D8: n | E8: n | F8: applied based on scenario
B9: Dak | D9: y | E9: y | F9: y
B10: Vloerhoogte | C10: plan_z | D10: n | E10: n | F10: y
A11: Buitenklimaat gegevens | B11: Locatie gegevens | D11: y | F11: N/A Standard value available for use, to be updated by Jaap
B12: Locatie gegevens Tgem | D12: y
B13: Locatie gegevens Tgem.zomer | D13: y
B14: Locatie gegevens Tgem.winter | D14: y
B15: Locatie gegevens Ezon.zomer | D15: y
B16: Locatie gegevensEzon.winter | D16: y
B17: Climate Change effect | D17: y
B18: Climate Change effect Tgem | D18: y
B19: Climate Change effect Tgem.zomer | D19: y
B20: Climate Change effect Tgem.winter | D20: y
B21: Climate Change effect Ezon.zomer | D21: y
B22: Climate Change effect Ezon.winter | D22: y
B23: Urban Heat Island | D23: y | F23: N/A depends on Dinos Script
B24: Urban Heat Island Tgem | D24: y
B25: Urban Heat Island Tgem.zomer | D25: y
B26: Urban Heat Island Tgem.winter | D26: y
B27: Bezonning gevel | D27: y
B28: Bezonning gevel Ezon.zomer | D28: y
B29: Bezonning gevel Ezon.winter | D29: y
B30: Berekend daglicht factor | D30: y | F30: N/A Standard value available for use, to be updated by Yara
A31: Installatie gegevens | B31: Ventilatiesysteem | F31: N/A to be filled in on excel. Same values apply to all buildings
B32: Koude/warmte
B33: Zonnecollector
B34: Douche wtw
B35: CO2 regeling ventilatie
A36: Constructie wijze | F36: N/A
